[2022-12-26T14:04:43.248+0000] {taskinstance.py:1165} INFO - Dependencies all met for <TaskInstance: exchange_rates.get_rate_EUR_RUB scheduled__2022-12-16T08:15:00+00:00 [queued]>
[2022-12-26T14:04:43.307+0000] {taskinstance.py:1165} INFO - Dependencies all met for <TaskInstance: exchange_rates.get_rate_EUR_RUB scheduled__2022-12-16T08:15:00+00:00 [queued]>
[2022-12-26T14:04:43.308+0000] {taskinstance.py:1362} INFO - 
--------------------------------------------------------------------------------
[2022-12-26T14:04:43.308+0000] {taskinstance.py:1363} INFO - Starting attempt 1 of 1
[2022-12-26T14:04:43.309+0000] {taskinstance.py:1364} INFO - 
--------------------------------------------------------------------------------
[2022-12-26T14:04:43.370+0000] {taskinstance.py:1383} INFO - Executing <Task(CurrencyScoopOperator): get_rate_EUR_RUB> on 2022-12-16 08:15:00+00:00
[2022-12-26T14:04:43.389+0000] {standard_task_runner.py:54} INFO - Started process 12378 to run task
[2022-12-26T14:04:43.418+0000] {standard_task_runner.py:82} INFO - Running: ['***', 'tasks', 'run', 'exchange_rates', 'get_rate_EUR_RUB', 'scheduled__2022-12-16T08:15:00+00:00', '--job-id', '6090', '--raw', '--subdir', 'DAGS_FOLDER/exchange_rates.py', '--cfg-path', '/tmp/tmpooadfvyr']
[2022-12-26T14:04:43.419+0000] {standard_task_runner.py:83} INFO - Job 6090: Subtask get_rate_EUR_RUB
[2022-12-26T14:04:43.422+0000] {dagbag.py:525} INFO - Filling up the DagBag from /opt/***/dags/exchange_rates.py
[2022-12-26T14:04:43.739+0000] {taskmixin.py:205} WARNING - Dependency <Task(CurrencyScoopOperator): get_rate_AMD_RUB>, insert_rate_AMD_RUB already registered for DAG: exchange_rates
[2022-12-26T14:04:43.746+0000] {taskmixin.py:205} WARNING - Dependency <Task(PostgresOperator): insert_rate_AMD_RUB>, get_rate_AMD_RUB already registered for DAG: exchange_rates
[2022-12-26T14:04:43.949+0000] {task_command.py:384} INFO - Running <TaskInstance: exchange_rates.get_rate_EUR_RUB scheduled__2022-12-16T08:15:00+00:00 [running]> on host d383fbf2a8e7
[2022-12-26T14:04:44.134+0000] {taskinstance.py:1592} INFO - Exporting the following env vars:
AIRFLOW_CTX_DAG_OWNER=***
AIRFLOW_CTX_DAG_ID=exchange_rates
AIRFLOW_CTX_TASK_ID=get_rate_EUR_RUB
AIRFLOW_CTX_EXECUTION_DATE=2022-12-16T08:15:00+00:00
AIRFLOW_CTX_TRY_NUMBER=1
AIRFLOW_CTX_DAG_RUN_ID=scheduled__2022-12-16T08:15:00+00:00
[2022-12-26T14:04:44.138+0000] {warnings.py:110} WARNING - /home/***/.local/lib/python3.7/site-packages/***/utils/context.py:204: AirflowContextDeprecationWarning: Accessing 'execution_date' from the template is deprecated and will be removed in a future version. Please use 'data_interval_start' or 'logical_date' instead.
  warnings.warn(_create_deprecation_warning(key, self._deprecation_replacements[key]))

[2022-12-26T14:04:44.157+0000] {base.py:71} INFO - Using connection ID 'currency_conn_id' for task execution.
[2022-12-26T14:04:44.598+0000] {taskinstance.py:1851} ERROR - Task failed with exception
Traceback (most recent call last):
  File "/opt/airflow/dags/exchange_rates.py", line 56, in execute
    return api.get_rate(context['execution_date'].date(), self.base_currency, self.currency)
  File "/opt/airflow/dags/exchange_rates.py", line 31, in get_rate
    response.raise_for_status()
  File "/home/airflow/.local/lib/python3.7/site-packages/requests/models.py", line 1021, in raise_for_status
    raise HTTPError(http_error_msg, response=self)
requests.exceptions.HTTPError: 426 Client Error: Upgrade Required for url: https://api.currencyscoop.com/v1/historical?base=EUR&symbols=RUB&api_key=***&date=2022-12-16
[2022-12-26T14:04:44.609+0000] {taskinstance.py:1406} INFO - Marking task as FAILED. dag_id=exchange_rates, task_id=get_rate_EUR_RUB, execution_date=20221216T081500, start_date=20221226T140443, end_date=20221226T140444
[2022-12-26T14:04:44.627+0000] {standard_task_runner.py:107} ERROR - Failed to execute job 6090 for task get_rate_EUR_RUB (426 Client Error: Upgrade Required for url: https://api.currencyscoop.com/v1/historical?base=EUR&symbols=RUB&api_key=***&date=2022-12-16; 12378)
[2022-12-26T14:04:44.669+0000] {local_task_job.py:164} INFO - Task exited with return code 1
[2022-12-26T14:04:44.731+0000] {local_task_job.py:273} INFO - 0 downstream tasks scheduled from follow-on schedule check
[2023-01-01T14:50:02.210+0000] {taskinstance.py:1165} INFO - Dependencies all met for <TaskInstance: exchange_rates.get_rate_EUR_RUB scheduled__2022-12-16T08:15:00+00:00 [queued]>
[2023-01-01T14:50:02.255+0000] {taskinstance.py:1165} INFO - Dependencies all met for <TaskInstance: exchange_rates.get_rate_EUR_RUB scheduled__2022-12-16T08:15:00+00:00 [queued]>
[2023-01-01T14:50:02.256+0000] {taskinstance.py:1362} INFO - 
--------------------------------------------------------------------------------
[2023-01-01T14:50:02.256+0000] {taskinstance.py:1363} INFO - Starting attempt 1 of 1
[2023-01-01T14:50:02.257+0000] {taskinstance.py:1364} INFO - 
--------------------------------------------------------------------------------
[2023-01-01T14:50:02.297+0000] {taskinstance.py:1383} INFO - Executing <Task(CurrencyScoopOperator): get_rate_EUR_RUB> on 2022-12-16 08:15:00+00:00
[2023-01-01T14:50:02.305+0000] {standard_task_runner.py:54} INFO - Started process 14201 to run task
[2023-01-01T14:50:02.319+0000] {standard_task_runner.py:82} INFO - Running: ['***', 'tasks', 'run', 'exchange_rates', 'get_rate_EUR_RUB', 'scheduled__2022-12-16T08:15:00+00:00', '--job-id', '12608', '--raw', '--subdir', 'DAGS_FOLDER/exchange_rates.py', '--cfg-path', '/tmp/tmpju665dan']
[2023-01-01T14:50:02.330+0000] {standard_task_runner.py:83} INFO - Job 12608: Subtask get_rate_EUR_RUB
[2023-01-01T14:50:02.336+0000] {dagbag.py:525} INFO - Filling up the DagBag from /opt/***/dags/exchange_rates.py
[2023-01-01T14:50:02.637+0000] {taskmixin.py:205} WARNING - Dependency <Task(CurrencyScoopOperator): get_rate_AMD_RUB>, insert_rate_AMD_RUB already registered for DAG: exchange_rates
[2023-01-01T14:50:02.638+0000] {taskmixin.py:205} WARNING - Dependency <Task(PostgresOperator): insert_rate_AMD_RUB>, get_rate_AMD_RUB already registered for DAG: exchange_rates
[2023-01-01T14:50:02.829+0000] {task_command.py:384} INFO - Running <TaskInstance: exchange_rates.get_rate_EUR_RUB scheduled__2022-12-16T08:15:00+00:00 [running]> on host d383fbf2a8e7
[2023-01-01T14:50:02.943+0000] {taskinstance.py:1592} INFO - Exporting the following env vars:
AIRFLOW_CTX_DAG_OWNER=***
AIRFLOW_CTX_DAG_ID=exchange_rates
AIRFLOW_CTX_TASK_ID=get_rate_EUR_RUB
AIRFLOW_CTX_EXECUTION_DATE=2022-12-16T08:15:00+00:00
AIRFLOW_CTX_TRY_NUMBER=1
AIRFLOW_CTX_DAG_RUN_ID=scheduled__2022-12-16T08:15:00+00:00
[2023-01-01T14:50:02.944+0000] {warnings.py:110} WARNING - /home/***/.local/lib/python3.7/site-packages/***/utils/context.py:204: AirflowContextDeprecationWarning: Accessing 'execution_date' from the template is deprecated and will be removed in a future version. Please use 'data_interval_start' or 'logical_date' instead.
  warnings.warn(_create_deprecation_warning(key, self._deprecation_replacements[key]))

[2023-01-01T14:50:02.954+0000] {base.py:71} INFO - Using connection ID 'currency_conn_id' for task execution.
[2023-01-01T14:50:07.975+0000] {taskinstance.py:1851} ERROR - Task failed with exception
Traceback (most recent call last):
  File "/home/airflow/.local/lib/python3.7/site-packages/urllib3/connectionpool.py", line 710, in urlopen
    chunked=chunked,
  File "/home/airflow/.local/lib/python3.7/site-packages/urllib3/connectionpool.py", line 386, in _make_request
    self._validate_conn(conn)
  File "/home/airflow/.local/lib/python3.7/site-packages/urllib3/connectionpool.py", line 1042, in _validate_conn
    conn.connect()
  File "/home/airflow/.local/lib/python3.7/site-packages/urllib3/connection.py", line 424, in connect
    tls_in_tls=tls_in_tls,
  File "/home/airflow/.local/lib/python3.7/site-packages/urllib3/util/ssl_.py", line 450, in ssl_wrap_socket
    sock, context, tls_in_tls, server_hostname=server_hostname
  File "/home/airflow/.local/lib/python3.7/site-packages/urllib3/util/ssl_.py", line 493, in _ssl_wrap_socket_impl
    return ssl_context.wrap_socket(sock, server_hostname=server_hostname)
  File "/usr/local/lib/python3.7/ssl.py", line 423, in wrap_socket
    session=session
  File "/usr/local/lib/python3.7/ssl.py", line 870, in _create
    self.do_handshake()
  File "/usr/local/lib/python3.7/ssl.py", line 1139, in do_handshake
    self._sslobj.do_handshake()
OSError: [Errno 0] Error

During handling of the above exception, another exception occurred:

Traceback (most recent call last):
  File "/home/airflow/.local/lib/python3.7/site-packages/requests/adapters.py", line 499, in send
    timeout=timeout,
  File "/home/airflow/.local/lib/python3.7/site-packages/urllib3/connectionpool.py", line 788, in urlopen
    method, url, error=e, _pool=self, _stacktrace=sys.exc_info()[2]
  File "/home/airflow/.local/lib/python3.7/site-packages/urllib3/util/retry.py", line 550, in increment
    raise six.reraise(type(error), error, _stacktrace)
  File "/home/airflow/.local/lib/python3.7/site-packages/urllib3/packages/six.py", line 769, in reraise
    raise value.with_traceback(tb)
  File "/home/airflow/.local/lib/python3.7/site-packages/urllib3/connectionpool.py", line 710, in urlopen
    chunked=chunked,
  File "/home/airflow/.local/lib/python3.7/site-packages/urllib3/connectionpool.py", line 386, in _make_request
    self._validate_conn(conn)
  File "/home/airflow/.local/lib/python3.7/site-packages/urllib3/connectionpool.py", line 1042, in _validate_conn
    conn.connect()
  File "/home/airflow/.local/lib/python3.7/site-packages/urllib3/connection.py", line 424, in connect
    tls_in_tls=tls_in_tls,
  File "/home/airflow/.local/lib/python3.7/site-packages/urllib3/util/ssl_.py", line 450, in ssl_wrap_socket
    sock, context, tls_in_tls, server_hostname=server_hostname
  File "/home/airflow/.local/lib/python3.7/site-packages/urllib3/util/ssl_.py", line 493, in _ssl_wrap_socket_impl
    return ssl_context.wrap_socket(sock, server_hostname=server_hostname)
  File "/usr/local/lib/python3.7/ssl.py", line 423, in wrap_socket
    session=session
  File "/usr/local/lib/python3.7/ssl.py", line 870, in _create
    self.do_handshake()
  File "/usr/local/lib/python3.7/ssl.py", line 1139, in do_handshake
    self._sslobj.do_handshake()
urllib3.exceptions.ProtocolError: ('Connection aborted.', OSError(0, 'Error'))

During handling of the above exception, another exception occurred:

Traceback (most recent call last):
  File "/opt/airflow/dags/exchange_rates.py", line 56, in execute
    return api.get_rate(context['execution_date'].date(), self.base_currency, self.currency)
  File "/opt/airflow/dags/exchange_rates.py", line 30, in get_rate
    response = requests.get(url, params=params)
  File "/home/airflow/.local/lib/python3.7/site-packages/requests/api.py", line 73, in get
    return request("get", url, params=params, **kwargs)
  File "/home/airflow/.local/lib/python3.7/site-packages/requests/api.py", line 59, in request
    return session.request(method=method, url=url, **kwargs)
  File "/home/airflow/.local/lib/python3.7/site-packages/requests/sessions.py", line 587, in request
    resp = self.send(prep, **send_kwargs)
  File "/home/airflow/.local/lib/python3.7/site-packages/requests/sessions.py", line 701, in send
    r = adapter.send(request, **kwargs)
  File "/home/airflow/.local/lib/python3.7/site-packages/requests/adapters.py", line 547, in send
    raise ConnectionError(err, request=request)
requests.exceptions.ConnectionError: ('Connection aborted.', OSError(0, 'Error'))
[2023-01-01T14:50:07.996+0000] {taskinstance.py:1406} INFO - Marking task as FAILED. dag_id=exchange_rates, task_id=get_rate_EUR_RUB, execution_date=20221216T081500, start_date=20230101T145002, end_date=20230101T145007
[2023-01-01T14:50:08.120+0000] {standard_task_runner.py:107} ERROR - Failed to execute job 12608 for task get_rate_EUR_RUB (('Connection aborted.', OSError(0, 'Error')); 14201)
[2023-01-01T14:50:08.170+0000] {local_task_job.py:164} INFO - Task exited with return code 1
[2023-01-01T14:50:08.228+0000] {local_task_job.py:273} INFO - 0 downstream tasks scheduled from follow-on schedule check
